<?xml version='1.0'?>
<robot name="demo_bot">

<link name="body"> 
 <pose>0 0 0.3 0 0 0</pose>
      
      <visual>
        <origin xyz="0 0 0" rpy="0 0 0"/>
        <geometry>
          <box size="1 0.5 0.5" />
        </geometry>
        <material name="blue">
        <color rgba="0 0.5 1 1"/>
        </material>
      </visual>

      <collision>
        <max_contacts>10</max_contacts>
        <origin xyz="0 0 0" rpy="0 0 0"/>
        <geometry>
          <box size="1 0.5 0.5" />
        </geometry>
      </collision>

      <inertial>
        <mass value="1"/>
        <inertia ixx="0.166667"  ixy="0"  ixz="0" iyy="0.166667" iyz="0" izz="0.166667" />
      </inertial>

</link>


<link name="right_wheel">
      

      <visual>
      <origin xyz="0 0 0" rpy="1.5707 0 0" />
        <geometry>
          <cylinder length="0.1" radius="0.3"/>
        </geometry>
        <material name="darkgray">
        <color rgba=".2 .2 .2 1"/>
        </material>
      </visual>
      
      <collision>
        <origin xyz="0 0 0" rpy="1.5707 0 0" />
        <geometry>
          <cylinder length="0.1" radius="0.3"/>
        </geometry>
      </collision>

      <inertial>
        <mass value="1"/>
        <inertia ixx="0.145833"  ixy="0"  ixz="0" iyy="0.145833" iyz="0" izz="0.125" />
      </inertial>
</link>

<link name="left_wheel">
      

      <visual>
       <origin xyz="0 0 0" rpy="1.5707 0 0" />
        <geometry>
          <cylinder length="0.1" radius="0.3"/>
        </geometry>
        <material name="darkgray">
        <color rgba=".2 .2 .2 1"/>
        </material>
      </visual>
      
      <collision>
        <origin xyz="0 0 0" rpy="1.5707 0 0" />
        <geometry>
          <cylinder length="0.1" radius="0.3"/>
        </geometry>
      </collision>

      <inertial>
        <mass value="1"/>
        <inertia ixx="0.145833"  ixy="0"  ixz="0" iyy="0.145833" iyz="0" izz="0.125" />
      </inertial>
</link>

<joint name="right_joint" type="continuous">
      <parent>body</parent>
      <child>right_wheel</child>
      <origin xyz="0 0.3 0" rpy="0 0 0"/>
      <axis xyz="0 1 0"/>
</joint>

<joint name="left_joint" type="continuous">
      <parent>body</parent>
      <child>right_wheel</child>
      <origin xyz="0 -0.3 0" rpy="0 0 0"/>
      <axis xyz="0 1 0"/>
</joint>

<gazebo reference="body">
  <material> Gazebo/Blue</material>
</gazebo>
<gazebo reference="left_wheel">
  <material> Gazebo/Red</material>
</gazebo>
<gazebo reference="right_wheel">
  <material> Gazebo/Red</material>
</gazebo>
  

<gazebo>
 <plugin name="differential_drive_controller" filename="libgazebo_ros_diff_drive.so">
  <alwaysOn>false</alwaysOn>
  <updateRate>40</updateRate>
  <wheelSeparation>0.6</wheelSeparation> 
  <wheelDiameter>0.6</wheelDiameter>
  <wheelAcceleration>1</wheelAcceleration>
  <wheelTorque>20</wheelTorque>
  <commandTopic>cmd_vel</commandTopic>
  <odometryTopic>odom</odometryTopic>
  <odometryFrame>odom</odometryFrame>
  <robotBaseFrame>body</robotBaseFrame>
  <legacyMode>false</legacyMode>
 </plugin>
</gazebo>


</robot>

